/home/user/anaconda3/lib/python3.11/site-packages/onnxruntime/capi/onnxruntime_inference_collection.py:69: UserWarning: Specified provider 'CUDAExecutionProvider' is not in available provider names.Available providers: 'AzureExecutionProvider, CPUExecutionProvider'
  warnings.warn(
Applied providers: ['CPUExecutionProvider'], with options: {'CPUExecutionProvider': {}}
find model: /home/user/.insightface/models/buffalo_l/1k3d68.onnx landmark_3d_68 ['None', 3, 192, 192] 0.0 1.0
Applied providers: ['CPUExecutionProvider'], with options: {'CPUExecutionProvider': {}}
find model: /home/user/.insightface/models/buffalo_l/2d106det.onnx landmark_2d_106 ['None', 3, 192, 192] 0.0 1.0
Applied providers: ['CPUExecutionProvider'], with options: {'CPUExecutionProvider': {}}
find model: /home/user/.insightface/models/buffalo_l/det_10g.onnx detection [1, 3, '?', '?'] 127.5 128.0
Applied providers: ['CPUExecutionProvider'], with options: {'CPUExecutionProvider': {}}
find model: /home/user/.insightface/models/buffalo_l/genderage.onnx genderage ['None', 3, 96, 96] 0.0 1.0
Applied providers: ['CPUExecutionProvider'], with options: {'CPUExecutionProvider': {}}
find model: /home/user/.insightface/models/buffalo_l/w600k_r50.onnx recognition ['None', 3, 112, 112] 127.5 127.5
set det-size: (320, 320)
/home/user/anaconda3/lib/python3.11/site-packages/insightface/utils/transform.py:68: FutureWarning: `rcond` parameter will change to the default of machine precision times ``max(M, N)`` where M and N are the input matrix dimensions.
To use the future default and silence this warning we advise to pass `rcond=None`, to keep using the old, explicitly pass `rcond=-1`.
  P = np.linalg.lstsq(X_homo, Y)[0].T # Affine matrix. 3 x 4
:::::bbox:::::: [1684, 729, 1876, 940]
Cropped faces saved.
# Iter: 0	Loss: 27.339
Traceback (most recent call last):
  File "/home/user/anaconda3/lib/python3.11/site-packages/PIL/Image.py", line 3098, in fromarray
    mode, rawmode = _fromarray_typemap[typekey]
                    ~~~~~~~~~~~~~~~~~~^^^^^^^^^
KeyError: ((1, 1, 1), '|u1')

The above exception was the direct cause of the following exception:

Traceback (most recent call last):
  File "/home/user/bob/fakeguard/guard.py", line 217, in <module>
    noised_img = generate_one("source_face.png", "target_face.png")
                 ^^^^^^^^^^^^^^^^^^^^^^^^^^^^^^^^^^^^^^^^^^^^^^^^^^
  File "/home/user/bob/fakeguard/guard.py", line 122, in generate_one
    diff_img = tensor2img(diff)
               ^^^^^^^^^^^^^^^^
  File "/home/user/bob/fakeguard/guard.py", line 51, in tensor2img
    cur_img = Image.fromarray(cur_img.astype(np.uint8))
              ^^^^^^^^^^^^^^^^^^^^^^^^^^^^^^^^^^^^^^^^^
  File "/home/user/anaconda3/lib/python3.11/site-packages/PIL/Image.py", line 3102, in fromarray
    raise TypeError(msg) from e
TypeError: Cannot handle this data type: (1, 1, 1), |u1
